Workbook

Sheet Sheet1
A1: sku | B1: الصنف | C1: السعر قبل العرض بالضريبة | D1: نسبة الخصم | E1: السعر بعد العرض بالضريبة | F1: بداية المدة | G1: نهاية المدة
A2: 20615010273 | B2: {=IFERROR(_xlfn.XLOOKUP(A2,Sheet2!$A$2:$A$1453,Sheet2!$B$2:$B$1453),_xlfn.XLOOKUP(A2,TEXT(Sheet2!$A$2:$A$1453,"0"),Sheet2!$B$2:$B$1453,""))} -> BABY JOY NO(6) XXL BOX JUMBO1X60 29252 | C2: 112.7 | D2: {=_xlfn.LET(_xlpm.v,IFERROR(_xlfn.XLOOKUP(A2,Sheet2!$A$2:$A$1453,Sheet2!$D$2:$D$1453),_xlfn.XLOOKUP(A2,TEXT(Sheet2!$A$2:$A$1453,"0"),Sheet2!$D$2:$D$1453,"")),IF(_xlpm.v="","",IF(_xlpm.v<1,_xlpm.v*100,_xlpm.v)))} -> 20 | E2: =IF(D2="","",C2*(1-D2/100)) -> 90.16 | F2: {=IFERROR(_xlfn.XLOOKUP(A2,Sheet2!$A$2:$A$1453,Sheet2!$F$2:$F$1453),_xlfn.XLOOKUP(A2,TEXT(Sheet2!$A$2:$A$1453,"0"),Sheet2!$F$2:$F$1453,""))} -> 26-7-2026 | G2: {=IFERROR(_xlfn.XLOOKUP(A2,Sheet2!$A$2:$A$1453,Sheet2!$G$2:$G$1453),_xlfn.XLOOKUP(A2,TEXT(Sheet2!$A$2:$A$1453,"0"),Sheet2!$G$2:$G$1453,""))} -> 29-7-2026
A3: 20615010012 | B3: {=IFERROR(_xlfn.XLOOKUP(A3,Sheet2!$A$2:$A$1453,Sheet2!$B$2:$B$1453),_xlfn.XLOOKUP(A3,TEXT(Sheet2!$A$2:$A$1453,"0"),Sheet2!$B$2:$B$1453,""))} -> BABY JOY NO-3 BOX 1X104 | C3: 112.7 | D3: {=_xlfn.LET(_xlpm.v,IFERROR(_xlfn.XLOOKUP(A3,Sheet2!$A$2:$A$1453,Sheet2!$D$2:$D$1453),_xlfn.XLOOKUP(A3,TEXT(Sheet2!$A$2:$A$1453,"0"),Sheet2!$D$2:$D$1453,"")),IF(_xlpm.v="","",IF(_xlpm.v<1,_xlpm.v*100,_xlpm.v)))} -> 20 | E3: =IF(D3="","",C3*(1-D3/100)) -> 90.16 | F3: {=IFERROR(_xlfn.XLOOKUP(A3,Sheet2!$A$2:$A$1453,Sheet2!$F$2:$F$1453),_xlfn.XLOOKUP(A3,TEXT(Sheet2!$A$2:$A$1453,"0"),Sheet2!$F$2:$F$1453,""))} -> 26-7-2026 | G3: {=IFERROR(_xlfn.XLOOKUP(A3,Sheet2!$A$2:$A$1453,Sheet2!$G$2:$G$1453),_xlfn.XLOOKUP(A3,TEXT(Sheet2!$A$2:$A$1453,"0"),Sheet2!$G$2:$G$1453,""))} -> 29-7-2026
A4: 20615010013 | B4: {=IFERROR(_xlfn.XLOOKUP(A4,Sheet2!$A$2:$A$1453,Sheet2!$B$2:$B$1453),_xlfn.XLOOKUP(A4,TEXT(Sheet2!$A$2:$A$1453,"0"),Sheet2!$B$2:$B$1453,""))} -> BABY JOY NO-4 BOX 1X96 | C4: 112.7 | D4: {=_xlfn.LET(_xlpm.v,IFERROR(_xlfn.XLOOKUP(A4,Sheet2!$A$2:$A$1453,Sheet2!$D$2:$D$1453),_xlfn.XLOOKUP(A4,TEXT(Sheet2!$A$2:$A$1453,"0"),Sheet2!$D$2:$D$1453,"")),IF(_xlpm.v="","",IF(_xlpm.v<1,_xlpm.v*100,_xlpm.v)))} -> 20 | E4: =IF(D4="","",C4*(1-D4/100)) -> 90.16 | F4: {=IFERROR(_xlfn.XLOOKUP(A4,Sheet2!$A$2:$A$1453,Sheet2!$F$2:$F$1453),_xlfn.XLOOKUP(A4,TEXT(Sheet2!$A$2:$A$1453,"0"),Sheet2!$F$2:$F$1453,""))} -> 26-7-2026 | G4: {=IFERROR(_xlfn.XLOOKUP(A4,Sheet2!$A$2:$A$1453,Sheet2!$G$2:$G$1453),_xlfn.XLOOKUP(A4,TEXT(Sheet2!$A$2:$A$1453,"0"),Sheet2!$G$2:$G$1453,""))} -> 29-7-2026
A5: 20615010014 | B5: {=IFERROR(_xlfn.XLOOKUP(A5,Sheet2!$A$2:$A$1453,Sheet2!$B$2:$B$1453),_xlfn.XLOOKUP(A5,TEXT(Sheet2!$A$2:$A$1453,"0"),Sheet2!$B$2:$B$1453,""))} -> BABY JOY NO-4+ BOX 1X88 | C5: 112.7 | D5: {=_xlfn.LET(_xlpm.v,IFERROR(_xlfn.XLOOKUP(A5,Sheet2!$A$2:$A$1453,Sheet2!$D$2:$D$1453),_xlfn.XLOOKUP(A5,TEXT(Sheet2!$A$2:$A$1453,"0"),Sheet2!$D$2:$D$1453,"")),IF(_xlpm.v="","",IF(_xlpm.v<1,_xlpm.v*100,_xlpm.v)))} -> 20 | E5: =IF(D5="","",C5*(1-D5/100)) -> 90.16 | F5: {=IFERROR(_xlfn.XLOOKUP(A5,Sheet2!$A$2:$A$1453,Sheet2!$F$2:$F$1453),_xlfn.XLOOKUP(A5,TEXT(Sheet2!$A$2:$A$1453,"0"),Sheet2!$F$2:$F$1453,""))} -> 26-7-2026 | G5: {=IFERROR(_xlfn.XLOOKUP(A5,Sheet2!$A$2:$A$1453,Sheet2!$G$2:$G$1453),_xlfn.XLOOKUP(A5,TEXT(Sheet2!$A$2:$A$1453,"0"),Sheet2!$G$2:$G$1453,""))} -> 29-7-2026
A6: 20615010015 | B6: {=IFERROR(_xlfn.XLOOKUP(A6,Sheet2!$A$2:$A$1453,Sheet2!$B$2:$B$1453),_xlfn.XLOOKUP(A6,TEXT(Sheet2!$A$2:$A$1453,"0"),Sheet2!$B$2:$B$1453,""))} -> BABY JOY NO-5 BOX 1X80 | C6: 112.7 | D6: {=_xlfn.LET(_xlpm.v,IFERROR(_xlfn.XLOOKUP(A6,Sheet2!$A$2:$A$1453,Sheet2!$D$2:$D$1453),_xlfn.XLOOKUP(A6,TEXT(Sheet2!$A$2:$A$1453,"0"),Sheet2!$D$2:$D$1453,"")),IF(_xlpm.v="","",IF(_xlpm.v<1,_xlpm.v*100,_xlpm.v)))} -> 20 | E6: =IF(D6="","",C6*(1-D6/100)) -> 90.16 | F6: {=IFERROR(_xlfn.XLOOKUP(A6,Sheet2!$A$2:$A$1453,Sheet2!$F$2:$F$1453),_xlfn.XLOOKUP(A6,TEXT(Sheet2!$A$2:$A$1453,"0"),Sheet2!$F$2:$F$1453,""))} -> 26-7-2026 | G6: {=IFERROR(_xlfn.XLOOKUP(A6,Sheet2!$A$2:$A$1453,Sheet2!$G$2:$G$1453),_xlfn.XLOOKUP(A6,TEXT(Sheet2!$A$2:$A$1453,"0"),Sheet2!$G$2:$G$1453,""))} -> 29-7-2026
A7: 20615010035 | B7: {=IFERROR(_xlfn.XLOOKUP(A7,Sheet2!$A$2:$A$1453,Sheet2!$B$2:$B$1453),_xlfn.XLOOKUP(A7,TEXT(Sheet2!$A$2:$A$1453,"0"),Sheet2!$B$2:$B$1453,""))} -> BABY JOY-1 BOX 1X136 29202 | C7: 112.7 | D7: {=_xlfn.LET(_xlpm.v,IFERROR(_xlfn.XLOOKUP(A7,Sheet2!$A$2:$A$1453,Sheet2!$D$2:$D$1453),_xlfn.XLOOKUP(A7,TEXT(Sheet2!$A$2:$A$1453,"0"),Sheet2!$D$2:$D$1453,"")),IF(_xlpm.v="","",IF(_xlpm.v<1,_xlpm.v*100,_xlpm.v)))} -> 20 | E7: =IF(D7="","",C7*(1-D7/100)) -> 90.16 | F7: {=IFERROR(_xlfn.XLOOKUP(A7,Sheet2!$A$2:$A$1453,Sheet2!$F$2:$F$1453),_xlfn.XLOOKUP(A7,TEXT(Sheet2!$A$2:$A$1453,"0"),Sheet2!$F$2:$F$1453,""))} -> 26-7-2026 | G7: {=IFERROR(_xlfn.XLOOKUP(A7,Sheet2!$A$2:$A$1453,Sheet2!$G$2:$G$1453),_xlfn.XLOOKUP(A7,TEXT(Sheet2!$A$2:$A$1453,"0"),Sheet2!$G$2:$G$1453,""))} -> 29-7-2026
A8: 20615010036 | B8: {=IFERROR(_xlfn.XLOOKUP(A8,Sheet2!$A$2:$A$1453,Sheet2!$B$2:$B$1453),_xlfn.XLOOKUP(A8,TEXT(Sheet2!$A$2:$A$1453,"0"),Sheet2!$B$2:$B$1453,""))} -> BABY JOY-2 BOX 1X136 29212 | C8: 112.7 | D8: {=_xlfn.LET(_xlpm.v,IFERROR(_xlfn.XLOOKUP(A8,Sheet2!$A$2:$A$1453,Sheet2!$D$2:$D$1453),_xlfn.XLOOKUP(A8,TEXT(Sheet2!$A$2:$A$1453,"0"),Sheet2!$D$2:$D$1453,"")),IF(_xlpm.v="","",IF(_xlpm.v<1,_xlpm.v*100,_xlpm.v)))} -> 20 | E8: =IF(D8="","",C8*(1-D8/100)) -> 90.16 | F8: {=IFERROR(_xlfn.XLOOKUP(A8,Sheet2!$A$2:$A$1453,Sheet2!$F$2:$F$1453),_xlfn.XLOOKUP(A8,TEXT(Sheet2!$A$2:$A$1453,"0"),Sheet2!$F$2:$F$1453,""))} -> 26-7-2026 | G8: {=IFERROR(_xlfn.XLOOKUP(A8,Sheet2!$A$2:$A$1453,Sheet2!$G$2:$G$1453),_xlfn.XLOOKUP(A8,TEXT(Sheet2!$A$2:$A$1453,"0"),Sheet2!$G$2:$G$1453,""))} -> 29-7-2026
A9: 20309501041 | B9: {=IFERROR(_xlfn.XLOOKUP(A9,Sheet2!$A$2:$A$1453,Sheet2!$B$2:$B$1453),_xlfn.XLOOKUP(A9,TEXT(Sheet2!$A$2:$A$1453,"0"),Sheet2!$B$2:$B$1453,""))} -> KOLE MAXI 306/1 DARK ASH BLOND 8 | C9: 17.95 | D9: {=_xlfn.LET(_xlpm.v,IFERROR(_xlfn.XLOOKUP(A9,Sheet2!$A$2:$A$1453,Sheet2!$D$2:$D$1453),_xlfn.XLOOKUP(A9,TEXT(Sheet2!$A$2:$A$1453,"0"),Sheet2!$D$2:$D$1453,"")),IF(_xlpm.v="","",IF(_xlpm.v<1,_xlpm.v*100,_xlpm.v)))} -> 10 | E9: =IF(D9="","",C9*(1-D9/100)) -> 16.155 | F9: {=IFERROR(_xlfn.XLOOKUP(A9,Sheet2!$A$2:$A$1453,Sheet2!$F$2:$F$1453),_xlfn.XLOOKUP(A9,TEXT(Sheet2!$A$2:$A$1453,"0"),Sheet2!$F$2:$F$1453,""))} -> 26-7-2026 | G9: {=IFERROR(_xlfn.XLOOKUP(A9,Sheet2!$A$2:$A$1453,Sheet2!$G$2:$G$1453),_xlfn.XLOOKUP(A9,TEXT(Sheet2!$A$2:$A$1453,"0"),Sheet2!$G$2:$G$1453,""))} -> 6-8-2026
A10: 20309010734 | B10: {=IFERROR(_xlfn.XLOOKUP(A10,Sheet2!$A$2:$A$1453,Sheet2!$B$2:$B$1453),_xlfn.XLOOKUP(A10,TEXT(Sheet2!$A$2:$A$1453,"0"),Sheet2!$B$2:$B$1453,""))} -> KOLE MAXI 308/1 LIGHT ASH BLONDE | C10: 17.95 | D10: {=_xlfn.LET(_xlpm.v,IFERROR(_xlfn.XLOOKUP(A10,Sheet2!$A$2:$A$1453,Sheet2!$D$2:$D$1453),_xlfn.XLOOKUP(A10,TEXT(Sheet2!$A$2:$A$1453,"0"),Sheet2!$D$2:$D$1453,"")),IF(_xlpm.v="","",IF(_xlpm.v<1,_xlpm.v*100,_xlpm.v)))} -> 10 | E10: =IF(D10="","",C10*(1-D10/100)) -> 16.155 | F10: {=IFERROR(_xlfn.XLOOKUP(A10,Sheet2!$A$2:$A$1453,Sheet2!$F$2:$F$1453),_xlfn.XLOOKUP(A10,TEXT(Sheet2!$A$2:$A$1453,"0"),Sheet2!$F$2:$F$1453,""))} -> 26-7-2026 | G10: {=IFERROR(_xlfn.XLOOKUP(A10,Sheet2!$A$2:$A$1453,Sheet2!$G$2:$G$1453),_xlfn.XLOOKUP(A10,TEXT(Sheet2!$A$2:$A$1453,"0"),Sheet2!$G$2:$G$1453,""))} -> 6-8-2026
A11: 2-09-163-030 | B11: {=IFERROR(_xlfn.XLOOKUP(A11,Sheet2!$A$2:$A$1453,Sheet2!$B$2:$B$1453),_xlfn.XLOOKUP(A11,TEXT(Sheet2!$A$2:$A$1453,"0"),Sheet2!$B$2:$B$1453,""))} -> QVBARSOAP/1APPLY,100GM/Conta | C11: 44.85 | D11: {=_xlfn.LET(_xlpm.v,IFERROR(_xlfn.XLOOKUP(A11,Sheet2!$A$2:$A$1453,Sheet2!$D$2:$D$1453),_xlfn.XLOOKUP(A11,TEXT(Sheet2!$A$2:$A$1453,"0"),Sheet2!$D$2:$D$1453,"")),IF(_xlpm.v="","",IF(_xlpm.v<1,_xlpm.v*100,_xlpm.v)))} -> 20 | E11: =IF(D11="","",C11*(1-D11/100)) -> 35.88 | F11: {=IFERROR(_xlfn.XLOOKUP(A11,Sheet2!$A$2:$A$1453,Sheet2!$F$2:$F$1453),_xlfn.XLOOKUP(A11,TEXT(Sheet2!$A$2:$A$1453,"0"),Sheet2!$F$2:$F$1453,""))} -> 26-7-2026 | G11: {=IFERROR(_xlfn.XLOOKUP(A11,Sheet2!$A$2:$A$1453,Sheet2!$G$2:$G$1453),_xlfn.XLOOKUP(A11,TEXT(Sheet2!$A$2:$A$1453,"0"),Sheet2!$G$2:$G$1453,""))} -> 6-8-2026
A12: 20312051410 | B12: {=IFERROR(_xlfn.XLOOKUP(A12,Sheet2!$A$2:$A$1453,Sheet2!$B$2:$B$1453),_xlfn.XLOOKUP(A12,TEXT(Sheet2!$A$2:$A$1453,"0"),Sheet2!$B$2:$B$1453,""))} -> WHITE GLO CHARCOAL DEEP S | C12: 33.14 | D12: {=_xlfn.LET(_xlpm.v,IFERROR(_xlfn.XLOOKUP(A12,Sheet2!$A$2:$A$1453,Sheet2!$D$2:$D$1453),_xlfn.XLOOKUP(A12,TEXT(Sheet2!$A$2:$A$1453,"0"),Sheet2!$D$2:$D$1453,"")),IF(_xlpm.v="","",IF(_xlpm.v<1,_xlpm.v*100,_xlpm.v)))} -> 30 | E12: =IF(D12="","",C12*(1-D12/100)) -> 23.198 | F12: {=IFERROR(_xlfn.XLOOKUP(A12,Sheet2!$A$2:$A$1453,Sheet2!$F$2:$F$1453),_xlfn.XLOOKUP(A12,TEXT(Sheet2!$A$2:$A$1453,"0"),Sheet2!$F$2:$F$1453,""))} -> 26-7-2026 | G12: {=IFERROR(_xlfn.XLOOKUP(A12,Sheet2!$A$2:$A$1453,Sheet2!$G$2:$G$1453),_xlfn.XLOOKUP(A12,TEXT(Sheet2!$A$2:$A$1453,"0"),Sheet2!$G$2:$G$1453,""))} -> 6-8-2026
A13: 20315040836 | B13: {=IFERROR(_xlfn.XLOOKUP(A13,Sheet2!$A$2:$A$1453,Sheet2!$B$2:$B$1453),_xlfn.XLOOKUP(A13,TEXT(Sheet2!$A$2:$A$1453,"0"),Sheet2!$B$2:$B$1453,""))} -> AVENT NATURAL GLASS BOTTLE 240ML | C13: 90.01 | D13: {=_xlfn.LET(_xlpm.v,IFERROR(_xlfn.XLOOKUP(A13,Sheet2!$A$2:$A$1453,Sheet2!$D$2:$D$1453),_xlfn.XLOOKUP(A13,TEXT(Sheet2!$A$2:$A$1453,"0"),Sheet2!$D$2:$D$1453,"")),IF(_xlpm.v="","",IF(_xlpm.v<1,_xlpm.v*100,_xlpm.v)))} -> 15 | E13: =IF(D13="","",C13*(1-D13/100)) -> 76.5085 | F13: {=IFERROR(_xlfn.XLOOKUP(A13,Sheet2!$A$2:$A$1453,Sheet2!$F$2:$F$1453),_xlfn.XLOOKUP(A13,TEXT(Sheet2!$A$2:$A$1453,"0"),Sheet2!$F$2:$F$1453,""))} -> 26-7-2026 | G13: {=IFERROR(_xlfn.XLOOKUP(A13,Sheet2!$A$2:$A$1453,Sheet2!$G$2:$G$1453),_xlfn.XLOOKUP(A13,TEXT(Sheet2!$A$2:$A$1453,"0"),Sheet2!$G$2:$G$1453,""))} -> 6-8-2026
A14: 20309502776 | B14: {=IFERROR(_xlfn.XLOOKUP(A14,Sheet2!$A$2:$A$1453,Sheet2!$B$2:$B$1453),_xlfn.XLOOKUP(A14,TEXT(Sheet2!$A$2:$A$1453,"0"),Sheet2!$B$2:$B$1453,""))} -> DORCO SHAI 4:FRA 200-4P,FOR WOMEN (3+1) IN POLY BAG- 580630 | C14: 28.18 | D14: {=_xlfn.LET(_xlpm.v,IFERROR(_xlfn.XLOOKUP(A14,Sheet2!$A$2:$A$1453,Sheet2!$D$2:$D$1453),_xlfn.XLOOKUP(A14,TEXT(Sheet2!$A$2:$A$1453,"0"),Sheet2!$D$2:$D$1453,"")),IF(_xlpm.v="","",IF(_xlpm.v<1,_xlpm.v*100,_xlpm.v)))} -> 25 | E14: =IF(D14="","",C14*(1-D14/100)) -> 21.135 | F14: {=IFERROR(_xlfn.XLOOKUP(A14,Sheet2!$A$2:$A$1453,Sheet2!$F$2:$F$1453),_xlfn.XLOOKUP(A14,TEXT(Sheet2!$A$2:$A$1453,"0"),Sheet2!$F$2:$F$1453,""))} -> 26-7-2026 | G14: {=IFERROR(_xlfn.XLOOKUP(A14,Sheet2!$A$2:$A$1453,Sheet2!$G$2:$G$1453),_xlfn.XLOOKUP(A14,TEXT(Sheet2!$A$2:$A$1453,"0"),Sheet2!$G$2:$G$1453,""))} -> 6-8-2026
A15: 20309504115 | B15: {=IFERROR(_xlfn.XLOOKUP(A15,Sheet2!$A$2:$A$1453,Sheet2!$B$2:$B$1453),_xlfn.XLOOKUP(A15,TEXT(Sheet2!$A$2:$A$1453,"0"),Sheet2!$B$2:$B$1453,""))} -> BIC FLEX 5 HYBRID B4 801048 | C15: 48.66 | D15: {=_xlfn.LET(_xlpm.v,IFERROR(_xlfn.XLOOKUP(A15,Sheet2!$A$2:$A$1453,Sheet2!$D$2:$D$1453),_xlfn.XLOOKUP(A15,TEXT(Sheet2!$A$2:$A$1453,"0"),Sheet2!$D$2:$D$1453,"")),IF(_xlpm.v="","",IF(_xlpm.v<1,_xlpm.v*100,_xlpm.v)))} -> 15 | E15: =IF(D15="","",C15*(1-D15/100)) -> 41.361 | F15: {=IFERROR(_xlfn.XLOOKUP(A15,Sheet2!$A$2:$A$1453,Sheet2!$F$2:$F$1453),_xlfn.XLOOKUP(A15,TEXT(Sheet2!$A$2:$A$1453,"0"),Sheet2!$F$2:$F$1453,""))} -> 26-7-2026 | G15: {=IFERROR(_xlfn.XLOOKUP(A15,Sheet2!$A$2:$A$1453,Sheet2!$G$2:$G$1453),_xlfn.XLOOKUP(A15,TEXT(Sheet2!$A$2:$A$1453,"0"),Sheet2!$G$2:$G$1453,""))} -> 6-8-2026
A16: 20309504114 | B16: {=IFERROR(_xlfn.XLOOKUP(A16,Sheet2!$A$2:$A$1453,Sheet2!$B$2:$B$1453),_xlfn.XLOOKUP(A16,TEXT(Sheet2!$A$2:$A$1453,"0"),Sheet2!$B$2:$B$1453,""))} -> BIC FLEX 3 HYBRID B4 801047 | C16: 24.32 | D16: {=_xlfn.LET(_xlpm.v,IFERROR(_xlfn.XLOOKUP(A16,Sheet2!$A$2:$A$1453,Sheet2!$D$2:$D$1453),_xlfn.XLOOKUP(A16,TEXT(Sheet2!$A$2:$A$1453,"0"),Sheet2!$D$2:$D$1453,"")),IF(_xlpm.v="","",IF(_xlpm.v<1,_xlpm.v*100,_xlpm.v)))} -> 15 | E16: =IF(D16="","",C16*(1-D16/100)) -> 20.672 | F16: {=IFERROR(_xlfn.XLOOKUP(A16,Sheet2!$A$2:$A$1453,Sheet2!$F$2:$F$1453),_xlfn.XLOOKUP(A16,TEXT(Sheet2!$A$2:$A$1453,"0"),Sheet2!$F$2:$F$1453,""))} -> 26-7-2026 | G16: {=IFERROR(_xlfn.XLOOKUP(A16,Sheet2!$A$2:$A$1453,Sheet2!$G$2:$G$1453),_xlfn.XLOOKUP(A16,TEXT(Sheet2!$A$2:$A$1453,"0"),Sheet2!$G$2:$G$1453,""))} -> 6-8-2026
A17: 20309504113 | B17: {=IFERROR(_xlfn.XLOOKUP(A17,Sheet2!$A$2:$A$1453,Sheet2!$B$2:$B$1453),_xlfn.XLOOKUP(A17,TEXT(Sheet2!$A$2:$A$1453,"0"),Sheet2!$B$2:$B$1453,""))} -> BIC SOLEIL ESCAPE 5B BLAD 2 | C17: 22.56 | D17: {=_xlfn.LET(_xlpm.v,IFERROR(_xlfn.XLOOKUP(A17,Sheet2!$A$2:$A$1453,Sheet2!$D$2:$D$1453),_xlfn.XLOOKUP(A17,TEXT(Sheet2!$A$2:$A$1453,"0"),Sheet2!$D$2:$D$1453,"")),IF(_xlpm.v="","",IF(_xlpm.v<1,_xlpm.v*100,_xlpm.v)))} -> 15 | E17: =IF(D17="","",C17*(1-D17/100)) -> 19.176 | F17: {=IFERROR(_xlfn.XLOOKUP(A17,Sheet2!$A$2:$A$1453,Sheet2!$F$2:$F$1453),_xlfn.XLOOKUP(A17,TEXT(Sheet2!$A$2:$A$1453,"0"),Sheet2!$F$2:$F$1453,""))} -> 26-7-2026 | G17: {=IFERROR(_xlfn.XLOOKUP(A17,Sheet2!$A$2:$A$1453,Sheet2!$G$2:$G$1453),_xlfn.XLOOKUP(A17,TEXT(Sheet2!$A$2:$A$1453,"0"),Sheet2!$G$2:$G$1453,""))} -> 6-8-2026
A18: 20309504112 | B18: {=IFERROR(_xlfn.XLOOKUP(A18,Sheet2!$A$2:$A$1453,Sheet2!$B$2:$B$1453),_xlfn.XLOOKUP(A18,TEXT(Sheet2!$A$2:$A$1453,"0"),Sheet2!$B$2:$B$1453,""))} -> BIC SOLEIL CLICK 3 SENSITIVE | C18: 27.43 | D18: {=_xlfn.LET(_xlpm.v,IFERROR(_xlfn.XLOOKUP(A18,Sheet2!$A$2:$A$1453,Sheet2!$D$2:$D$1453),_xlfn.XLOOKUP(A18,TEXT(Sheet2!$A$2:$A$1453,"0"),Sheet2!$D$2:$D$1453,"")),IF(_xlpm.v="","",IF(_xlpm.v<1,_xlpm.v*100,_xlpm.v)))} -> 15 | E18: =IF(D18="","",C18*(1-D18/100)) -> 23.3155 | F18: {=IFERROR(_xlfn.XLOOKUP(A18,Sheet2!$A$2:$A$1453,Sheet2!$F$2:$F$1453),_xlfn.XLOOKUP(A18,TEXT(Sheet2!$A$2:$A$1453,"0"),Sheet2!$F$2:$F$1453,""))} -> 26-7-2026 | G18: {=IFERROR(_xlfn.XLOOKUP(A18,Sheet2!$A$2:$A$1453,Sheet2!$G$2:$G$1453),_xlfn.XLOOKUP(A18,TEXT(Sheet2!$A$2:$A$1453,"0"),Sheet2!$G$2:$G$1453,""))} -> 6-8-2026
A19: 20309504111 | B19: {=IFERROR(_xlfn.XLOOKUP(A19,Sheet2!$A$2:$A$1453,Sheet2!$B$2:$B$1453),_xlfn.XLOOKUP(A19,TEXT(Sheet2!$A$2:$A$1453,"0"),Sheet2!$B$2:$B$1453,""))} -> BIC SOLEIL CLICK 3 B4 10 80104 | C19: 24.77 | D19: {=_xlfn.LET(_xlpm.v,IFERROR(_xlfn.XLOOKUP(A19,Sheet2!$A$2:$A$1453,Sheet2!$D$2:$D$1453),_xlfn.XLOOKUP(A19,TEXT(Sheet2!$A$2:$A$1453,"0"),Sheet2!$D$2:$D$1453,"")),IF(_xlpm.v="","",IF(_xlpm.v<1,_xlpm.v*100,_xlpm.v)))} -> 15 | E19: =IF(D19="","",C19*(1-D19/100)) -> 21.0545 | F19: {=IFERROR(_xlfn.XLOOKUP(A19,Sheet2!$A$2:$A$1453,Sheet2!$F$2:$F$1453),_xlfn.XLOOKUP(A19,TEXT(Sheet2!$A$2:$A$1453,"0"),Sheet2!$F$2:$F$1453,""))} -> 26-7-2026 | G19: {=IFERROR(_xlfn.XLOOKUP(A19,Sheet2!$A$2:$A$1453,Sheet2!$G$2:$G$1453),_xlfn.XLOOKUP(A19,TEXT(Sheet2!$A$2:$A$1453,"0"),Sheet2!$G$2:$G$1453,""))} -> 6-8-2026
A20: 20309504110 | B20: {=IFERROR(_xlfn.XLOOKUP(A20,Sheet2!$A$2:$A$1453,Sheet2!$B$2:$B$1453),_xlfn.XLOOKUP(A20,TEXT(Sheet2!$A$2:$A$1453,"0"),Sheet2!$B$2:$B$1453,""))} -> BIC 3 MISS SOLEIL SENSITIVE | C20: 24.77 | D20: {=_xlfn.LET(_xlpm.v,IFERROR(_xlfn.XLOOKUP(A20,Sheet2!$A$2:$A$1453,Sheet2!$D$2:$D$1453),_xlfn.XLOOKUP(A20,TEXT(Sheet2!$A$2:$A$1453,"0"),Sheet2!$D$2:$D$1453,"")),IF(_xlpm.v="","",IF(_xlpm.v<1,_xlpm.v*100,_xlpm.v)))} -> 15 | E20: =IF(D20="","",C20*(1-D20/100)) -> 21.0545 | F20: {=IFERROR(_xlfn.XLOOKUP(A20,Sheet2!$A$2:$A$1453,Sheet2!$F$2:$F$1453),_xlfn.XLOOKUP(A20,TEXT(Sheet2!$A$2:$A$1453,"0"),Sheet2!$F$2:$F$1453,""))} -> 26-7-2026 | G20: {=IFERROR(_xlfn.XLOOKUP(A20,Sheet2!$A$2:$A$1453,Sheet2!$G$2:$G$1453),_xlfn.XLOOKUP(A20,TEXT(Sheet2!$A$2:$A$1453,"0"),Sheet2!$G$2:$G$1453,""))} -> 6-8-2026
A21: 20309504109 | B21: {=IFERROR(_xlfn.XLOOKUP(A21,Sheet2!$A$2:$A$1453,Sheet2!$B$2:$B$1453),_xlfn.XLOOKUP(A21,TEXT(Sheet2!$A$2:$A$1453,"0"),Sheet2!$B$2:$B$1453,""))} -> BIC 3 ACTION P12 8+4 801040 | C21: 26.09 | D21: {=_xlfn.LET(_xlpm.v,IFERROR(_xlfn.XLOOKUP(A21,Sheet2!$A$2:$A$1453,Sheet2!$D$2:$D$1453),_xlfn.XLOOKUP(A21,TEXT(Sheet2!$A$2:$A$1453,"0"),Sheet2!$D$2:$D$1453,"")),IF(_xlpm.v="","",IF(_xlpm.v<1,_xlpm.v*100,_xlpm.v)))} -> 15 | E21: =IF(D21="","",C21*(1-D21/100)) -> 22.1765 | F21: {=IFERROR(_xlfn.XLOOKUP(A21,Sheet2!$A$2:$A$1453,Sheet2!$F$2:$F$1453),_xlfn.XLOOKUP(A21,TEXT(Sheet2!$A$2:$A$1453,"0"),Sheet2!$F$2:$F$1453,""))} -> 26-7-2026 | G21: {=IFERROR(_xlfn.XLOOKUP(A21,Sheet2!$A$2:$A$1453,Sheet2!$G$2:$G$1453),_xlfn.XLOOKUP(A21,TEXT(Sheet2!$A$2:$A$1453,"0"),Sheet2!$G$2:$G$1453,""))} -> 6-8-2026
A22: 20309504108 | B22: {=IFERROR(_xlfn.XLOOKUP(A22,Sheet2!$A$2:$A$1453,Sheet2!$B$2:$B$1453),_xlfn.XLOOKUP(A22,TEXT(Sheet2!$A$2:$A$1453,"0"),Sheet2!$B$2:$B$1453,""))} -> BIC 4 SOLEIL BELLA 3+1 801035 | C22: 27.43 | D22: {=_xlfn.LET(_xlpm.v,IFERROR(_xlfn.XLOOKUP(A22,Sheet2!$A$2:$A$1453,Sheet2!$D$2:$D$1453),_xlfn.XLOOKUP(A22,TEXT(Sheet2!$A$2:$A$1453,"0"),Sheet2!$D$2:$D$1453,"")),IF(_xlpm.v="","",IF(_xlpm.v<1,_xlpm.v*100,_xlpm.v)))} -> 15 | E22: =IF(D22="","",C22*(1-D22/100)) -> 23.3155 | F22: {=IFERROR(_xlfn.XLOOKUP(A22,Sheet2!$A$2:$A$1453,Sheet2!$F$2:$F$1453),_xlfn.XLOOKUP(A22,TEXT(Sheet2!$A$2:$A$1453,"0"),Sheet2!$F$2:$F$1453,""))} -> 26-7-2026 | G22: {=IFERROR(_xlfn.XLOOKUP(A22,Sheet2!$A$2:$A$1453,Sheet2!$G$2:$G$1453),_xlfn.XLOOKUP(A22,TEXT(Sheet2!$A$2:$A$1453,"0"),Sheet2!$G$2:$G$1453,""))} -> 6-8-2026
A23: 20309504107 | B23: {=IFERROR(_xlfn.XLOOKUP(A23,Sheet2!$A$2:$A$1453,Sheet2!$B$2:$B$1453),_xlfn.XLOOKUP(A23,TEXT(Sheet2!$A$2:$A$1453,"0"),Sheet2!$B$2:$B$1453,""))} -> BIC 3 SOLEIL SCENT 4+2 801034 | C23: 27.43 | D23: {=_xlfn.LET(_xlpm.v,IFERROR(_xlfn.XLOOKUP(A23,Sheet2!$A$2:$A$1453,Sheet2!$D$2:$D$1453),_xlfn.XLOOKUP(A23,TEXT(Sheet2!$A$2:$A$1453,"0"),Sheet2!$D$2:$D$1453,"")),IF(_xlpm.v="","",IF(_xlpm.v<1,_xlpm.v*100,_xlpm.v)))} -> 15 | E23: =IF(D23="","",C23*(1-D23/100)) -> 23.3155 | F23: {=IFERROR(_xlfn.XLOOKUP(A23,Sheet2!$A$2:$A$1453,Sheet2!$F$2:$F$1453),_xlfn.XLOOKUP(A23,TEXT(Sheet2!$A$2:$A$1453,"0"),Sheet2!$F$2:$F$1453,""))} -> 26-7-2026 | G23: {=IFERROR(_xlfn.XLOOKUP(A23,Sheet2!$A$2:$A$1453,Sheet2!$G$2:$G$1453),_xlfn.XLOOKUP(A23,TEXT(Sheet2!$A$2:$A$1453,"0"),Sheet2!$G$2:$G$1453,""))} -> 6-8-2026
... A48: 20309504151 | B48: {=IFERROR(_xlfn.XLOOKUP(A48,Sheet2!$A$2:$A$1453,Sheet2!$B$2:$B$1453),_xlfn.XLOOKUP(A48,TEXT(Sheet2!$A$2:$A$1453,"0"),Sheet2!$B$2:$B$1453,""))} -> FRESH TOUNG BRUSH ADULT 92792 | C48: 18.7 | D48: {=_xlfn.LET(_xlpm.v,IFERROR(_xlfn.XLOOKUP(A48,Sheet2!$A$2:$A$1453,Sheet2!$D$2:$D$1453),_xlfn.XLOOKUP(A48,TEXT(Sheet2!$A$2:$A$1453,"0"),Sheet2!$D$2:$D$1453,"")),IF(_xlpm.v="","",IF(_xlpm.v<1,_xlpm.v*100,_xlpm.v)))} -> 10 | E48: =IF(D48="","",C48*(1-D48/100)) -> 16.83 | F48: {=IFERROR(_xlfn.XLOOKUP(A48,Sheet2!$A$2:$A$1453,Sheet2!$F$2:$F$1453),_xlfn.XLOOKUP(A48,TEXT(Sheet2!$A$2:$A$1453,"0"),Sheet2!$F$2:$F$1453,""))} -> 26-7-2026 | G48: {=IFERROR(_xlfn.XLOOKUP(A48,Sheet2!$A$2:$A$1453,Sheet2!$G$2:$G$1453),_xlfn.XLOOKUP(A48,TEXT(Sheet2!$A$2:$A$1453,"0"),Sheet2!$G$2:$G$1453,""))} -> 6-8-2026
A49: 1-03-186-068 | B49: {=IFERROR(_xlfn.XLOOKUP(A49,Sheet2!$A$2:$A$1453,Sheet2!$B$2:$B$1453),_xlfn.XLOOKUP(A49,TEXT(Sheet2!$A$2:$A$1453,"0"),Sheet2!$B$2:$B$1453,""))} -> NQ ARGITONE ml Syrup, 100 ML/BOTTLE | C49: 150 | D49: {=_xlfn.LET(_xlpm.v,IFERROR(_xlfn.XLOOKUP(A49,Sheet2!$A$2:$A$1453,Sheet2!$D$2:$D$1453),_xlfn.XLOOKUP(A49,TEXT(Sheet2!$A$2:$A$1453,"0"),Sheet2!$D$2:$D$1453,"")),IF(_xlpm.v="","",IF(_xlpm.v<1,_xlpm.v*100,_xlpm.v)))} -> 33 | E49: =IF(D49="","",C49*(1-D49/100)) -> 100.5 | F49: {=IFERROR(_xlfn.XLOOKUP(A49,Sheet2!$A$2:$A$1453,Sheet2!$F$2:$F$1453),_xlfn.XLOOKUP(A49,TEXT(Sheet2!$A$2:$A$1453,"0"),Sheet2!$F$2:$F$1453,""))} -> 26-7-2026 | G49: {=IFERROR(_xlfn.XLOOKUP(A49,Sheet2!$A$2:$A$1453,Sheet2!$G$2:$G$1453),_xlfn.XLOOKUP(A49,TEXT(Sheet2!$A$2:$A$1453,"0"),Sheet2!$G$2:$G$1453,""))} -> 6-8-2026
A50: 30420010756 | B50: {=IFERROR(_xlfn.XLOOKUP(A50,Sheet2!$A$2:$A$1453,Sheet2!$B$2:$B$1453),_xlfn.XLOOKUP(A50,TEXT(Sheet2!$A$2:$A$1453,"0"),Sheet2!$B$2:$B$1453,""))} -> SOFFISOF ADULT DIAPER XXL 111318 | C50: 75 | D50: {=_xlfn.LET(_xlpm.v,IFERROR(_xlfn.XLOOKUP(A50,Sheet2!$A$2:$A$1453,Sheet2!$D$2:$D$1453),_xlfn.XLOOKUP(A50,TEXT(Sheet2!$A$2:$A$1453,"0"),Sheet2!$D$2:$D$1453,"")),IF(_xlpm.v="","",IF(_xlpm.v<1,_xlpm.v*100,_xlpm.v)))} -> 10 | E50: =IF(D50="","",C50*(1-D50/100)) -> 67.5 | F50: {=IFERROR(_xlfn.XLOOKUP(A50,Sheet2!$A$2:$A$1453,Sheet2!$F$2:$F$1453),_xlfn.XLOOKUP(A50,TEXT(Sheet2!$A$2:$A$1453,"0"),Sheet2!$F$2:$F$1453,""))} -> 26-7-2026 | G50: {=IFERROR(_xlfn.XLOOKUP(A50,Sheet2!$A$2:$A$1453,Sheet2!$G$2:$G$1453),_xlfn.XLOOKUP(A50,TEXT(Sheet2!$A$2:$A$1453,"0"),Sheet2!$G$2:$G$1453,""))} -> 6-8-2026
A51: 1-03-044-032 | B51: {=IFERROR(_xlfn.XLOOKUP(A51,Sheet2!$A$2:$A$1453,Sheet2!$B$2:$B$1453),_xlfn.XLOOKUP(A51,TEXT(Sheet2!$A$2:$A$1453,"0"),Sheet2!$B$2:$B$1453,""))} -> BIOFAR PHYTO DIGESTION Effervescent Tablet, 6 TABLET/CONTAINER | C51: 40.25 | D51: {=_xlfn.LET(_xlpm.v,IFERROR(_xlfn.XLOOKUP(A51,Sheet2!$A$2:$A$1453,Sheet2!$D$2:$D$1453),_xlfn.XLOOKUP(A51,TEXT(Sheet2!$A$2:$A$1453,"0"),Sheet2!$D$2:$D$1453,"")),IF(_xlpm.v="","",IF(_xlpm.v<1,_xlpm.v*100,_xlpm.v)))} -> 40 | E51: =IF(D51="","",C51*(1-D51/100)) -> 24.15 | F51: {=IFERROR(_xlfn.XLOOKUP(A51,Sheet2!$A$2:$A$1453,Sheet2!$F$2:$F$1453),_xlfn.XLOOKUP(A51,TEXT(Sheet2!$A$2:$A$1453,"0"),Sheet2!$F$2:$F$1453,""))} -> 26-7-2026 | G51: {=IFERROR(_xlfn.XLOOKUP(A51,Sheet2!$A$2:$A$1453,Sheet2!$G$2:$G$1453),_xlfn.XLOOKUP(A51,TEXT(Sheet2!$A$2:$A$1453,"0"),Sheet2!$G$2:$G$1453,""))} -> 6-8-2026
A52: 1-03-044-031 | B52: {=IFERROR(_xlfn.XLOOKUP(A52,Sheet2!$A$2:$A$1453,Sheet2!$B$2:$B$1453),_xlfn.XLOOKUP(A52,TEXT(Sheet2!$A$2:$A$1453,"0"),Sheet2!$B$2:$B$1453,""))} -> BIOFAR VITAMIN B complex Effervescent Tablet, 20 TABLET/CONTAINER | C52: 35.65 | D52: {=_xlfn.LET(_xlpm.v,IFERROR(_xlfn.XLOOKUP(A52,Sheet2!$A$2:$A$1453,Sheet2!$D$2:$D$1453),_xlfn.XLOOKUP(A52,TEXT(Sheet2!$A$2:$A$1453,"0"),Sheet2!$D$2:$D$1453,"")),IF(_xlpm.v="","",IF(_xlpm.v<1,_xlpm.v*100,_xlpm.v)))} -> 40 | E52: =IF(D52="","",C52*(1-D52/100)) -> 21.39 | F52: {=IFERROR(_xlfn.XLOOKUP(A52,Sheet2!$A$2:$A$1453,Sheet2!$F$2:$F$1453),_xlfn.XLOOKUP(A52,TEXT(Sheet2!$A$2:$A$1453,"0"),Sheet2!$F$2:$F$1453,""))} -> 26-7-2026 | G52: {=IFERROR(_xlfn.XLOOKUP(A52,Sheet2!$A$2:$A$1453,Sheet2!$G$2:$G$1453),_xlfn.XLOOKUP(A52,TEXT(Sheet2!$A$2:$A$1453,"0"),Sheet2!$G$2:$G$1453,""))} -> 6-8-2026
A53: 1-03-044-030 | B53: {=IFERROR(_xlfn.XLOOKUP(A53,Sheet2!$A$2:$A$1453,Sheet2!$B$2:$B$1453),_xlfn.XLOOKUP(A53,TEXT(Sheet2!$A$2:$A$1453,"0"),Sheet2!$B$2:$B$1453,""))} -> BIOFAR KIDS MULTIVITAMIN Effervescent Tablet, 20 TABLET/CONTAINER | C53: 40.25 | D53: {=_xlfn.LET(_xlpm.v,IFERROR(_xlfn.XLOOKUP(A53,Sheet2!$A$2:$A$1453,Sheet2!$D$2:$D$1453),_xlfn.XLOOKUP(A53,TEXT(Sheet2!$A$2:$A$1453,"0"),Sheet2!$D$2:$D$1453,"")),IF(_xlpm.v="","",IF(_xlpm.v<1,_xlpm.v*100,_xlpm.v)))} -> 40 | E53: =IF(D53="","",C53*(1-D53/100)) -> 24.15 | F53: {=IFERROR(_xlfn.XLOOKUP(A53,Sheet2!$A$2:$A$1453,Sheet2!$F$2:$F$1453),_xlfn.XLOOKUP(A53,TEXT(Sheet2!$A$2:$A$1453,"0"),Sheet2!$F$2:$F$1453,""))} -> 26-7-2026 | G53: {=IFERROR(_xlfn.XLOOKUP(A53,Sheet2!$A$2:$A$1453,Sheet2!$G$2:$G$1453),_xlfn.XLOOKUP(A53,TEXT(Sheet2!$A$2:$A$1453,"0"),Sheet2!$G$2:$G$1453,""))} -> 6-8-2026
A54: 1-03-044-028 | B54: {=IFERROR(_xlfn.XLOOKUP(A54,Sheet2!$A$2:$A$1453,Sheet2!$B$2:$B$1453),_xlfn.XLOOKUP(A54,TEXT(Sheet2!$A$2:$A$1453,"0"),Sheet2!$B$2:$B$1453,""))} -> BIOFAR IRON FOLIC ACID Effervescent Tablet, 20 TABLET/CONTAINER | C54: 40.25 | D54: {=_xlfn.LET(_xlpm.v,IFERROR(_xlfn.XLOOKUP(A54,Sheet2!$A$2:$A$1453,Sheet2!$D$2:$D$1453),_xlfn.XLOOKUP(A54,TEXT(Sheet2!$A$2:$A$1453,"0"),Sheet2!$D$2:$D$1453,"")),IF(_xlpm.v="","",IF(_xlpm.v<1,_xlpm.v*100,_xlpm.v)))} -> 40 | E54: =IF(D54="","",C54*(1-D54/100)) -> 24.15 | F54: {=IFERROR(_xlfn.XLOOKUP(A54,Sheet2!$A$2:$A$1453,Sheet2!$F$2:$F$1453),_xlfn.XLOOKUP(A54,TEXT(Sheet2!$A$2:$A$1453,"0"),Sheet2!$F$2:$F$1453,""))} -> 26-7-2026 | G54: {=IFERROR(_xlfn.XLOOKUP(A54,Sheet2!$A$2:$A$1453,Sheet2!$G$2:$G$1453),_xlfn.XLOOKUP(A54,TEXT(Sheet2!$A$2:$A$1453,"0"),Sheet2!$G$2:$G$1453,""))} -> 6-8-2026
A55: 20309012316 | B55: {=IFERROR(_xlfn.XLOOKUP(A55,Sheet2!$A$2:$A$1453,Sheet2!$B$2:$B$1453),_xlfn.XLOOKUP(A55,TEXT(Sheet2!$A$2:$A$1453,"0"),Sheet2!$B$2:$B$1453,""))} -> PANTENE SHAMPO DAILY CARE 2X1 375 | C55: 14.84 | D55: {=_xlfn.LET(_xlpm.v,IFERROR(_xlfn.XLOOKUP(A55,Sheet2!$A$2:$A$1453,Sheet2!$D$2:$D$1453),_xlfn.XLOOKUP(A55,TEXT(Sheet2!$A$2:$A$1453,"0"),Sheet2!$D$2:$D$1453,"")),IF(_xlpm.v="","",IF(_xlpm.v<1,_xlpm.v*100,_xlpm.v)))} -> 15 | E55: =IF(D55="","",C55*(1-D55/100)) -> 12.614 | F55: {=IFERROR(_xlfn.XLOOKUP(A55,Sheet2!$A$2:$A$1453,Sheet2!$F$2:$F$1453),_xlfn.XLOOKUP(A55,TEXT(Sheet2!$A$2:$A$1453,"0"),Sheet2!$F$2:$F$1453,""))} -> 26-7-2026 | G55: {=IFERROR(_xlfn.XLOOKUP(A55,Sheet2!$A$2:$A$1453,Sheet2!$G$2:$G$1453),_xlfn.XLOOKUP(A55,TEXT(Sheet2!$A$2:$A$1453,"0"),Sheet2!$G$2:$G$1453,""))} -> 6-8-2026
A56: 20309012315 | B56: {=IFERROR(_xlfn.XLOOKUP(A56,Sheet2!$A$2:$A$1453,Sheet2!$B$2:$B$1453),_xlfn.XLOOKUP(A56,TEXT(Sheet2!$A$2:$A$1453,"0"),Sheet2!$B$2:$B$1453,""))} -> PANTENE SHAMPOO MOISTARE RENEW | C56: 14.84 | D56: {=_xlfn.LET(_xlpm.v,IFERROR(_xlfn.XLOOKUP(A56,Sheet2!$A$2:$A$1453,Sheet2!$D$2:$D$1453),_xlfn.XLOOKUP(A56,TEXT(Sheet2!$A$2:$A$1453,"0"),Sheet2!$D$2:$D$1453,"")),IF(_xlpm.v="","",IF(_xlpm.v<1,_xlpm.v*100,_xlpm.v)))} -> 15 | E56: =IF(D56="","",C56*(1-D56/100)) -> 12.614 | F56: {=IFERROR(_xlfn.XLOOKUP(A56,Sheet2!$A$2:$A$1453,Sheet2!$F$2:$F$1453),_xlfn.XLOOKUP(A56,TEXT(Sheet2!$A$2:$A$1453,"0"),Sheet2!$F$2:$F$1453,""))} -> 26-7-2026 | G56: {=IFERROR(_xlfn.XLOOKUP(A56,Sheet2!$A$2:$A$1453,Sheet2!$G$2:$G$1453),_xlfn.XLOOKUP(A56,TEXT(Sheet2!$A$2:$A$1453,"0"),Sheet2!$G$2:$G$1453,""))} -> 6-8-2026
A57: 20309012314 | B57: {=IFERROR(_xlfn.XLOOKUP(A57,Sheet2!$A$2:$A$1453,Sheet2!$B$2:$B$1453),_xlfn.XLOOKUP(A57,TEXT(Sheet2!$A$2:$A$1453,"0"),Sheet2!$B$2:$B$1453,""))} -> PANTENE SHAMPOO SHEER VALUME 37 | C57: 14.84 | D57: {=_xlfn.LET(_xlpm.v,IFERROR(_xlfn.XLOOKUP(A57,Sheet2!$A$2:$A$1453,Sheet2!$D$2:$D$1453),_xlfn.XLOOKUP(A57,TEXT(Sheet2!$A$2:$A$1453,"0"),Sheet2!$D$2:$D$1453,"")),IF(_xlpm.v="","",IF(_xlpm.v<1,_xlpm.v*100,_xlpm.v)))} -> 15 | E57: =IF(D57="","",C57*(1-D57/100)) -> 12.614 | F57: {=IFERROR(_xlfn.XLOOKUP(A57,Sheet2!$A$2:$A$1453,Sheet2!$F$2:$F$1453),_xlfn.XLOOKUP(A57,TEXT(Sheet2!$A$2:$A$1453,"0"),Sheet2!$F$2:$F$1453,""))} -> 26-7-2026 | G57: {=IFERROR(_xlfn.XLOOKUP(A57,Sheet2!$A$2:$A$1453,Sheet2!$G$2:$G$1453),_xlfn.XLOOKUP(A57,TEXT(Sheet2!$A$2:$A$1453,"0"),Sheet2!$G$2:$G$1453,""))} -> 6-8-2026
A58: 20309012313 | B58: {=IFERROR(_xlfn.XLOOKUP(A58,Sheet2!$A$2:$A$1453,Sheet2!$B$2:$B$1453),_xlfn.XLOOKUP(A58,TEXT(Sheet2!$A$2:$A$1453,"0"),Sheet2!$B$2:$B$1453,""))} -> PANTENE SHAMPOO MILKY DAMAGE R | C58: 14.84 | D58: {=_xlfn.LET(_xlpm.v,IFERROR(_xlfn.XLOOKUP(A58,Sheet2!$A$2:$A$1453,Sheet2!$D$2:$D$1453),_xlfn.XLOOKUP(A58,TEXT(Sheet2!$A$2:$A$1453,"0"),Sheet2!$D$2:$D$1453,"")),IF(_xlpm.v="","",IF(_xlpm.v<1,_xlpm.v*100,_xlpm.v)))} -> 15 | E58: =IF(D58="","",C58*(1-D58/100)) -> 12.614 | F58: {=IFERROR(_xlfn.XLOOKUP(A58,Sheet2!$A$2:$A$1453,Sheet2!$F$2:$F$1453),_xlfn.XLOOKUP(A58,TEXT(Sheet2!$A$2:$A$1453,"0"),Sheet2!$F$2:$F$1453,""))} -> 26-7-2026 | G58: {=IFERROR(_xlfn.XLOOKUP(A58,Sheet2!$A$2:$A$1453,Sheet2!$G$2:$G$1453),_xlfn.XLOOKUP(A58,TEXT(Sheet2!$A$2:$A$1453,"0"),Sheet2!$G$2:$G$1453,""))} -> 6-8-2026
A59: 20309012312 | B59: {=IFERROR(_xlfn.XLOOKUP(A59,Sheet2!$A$2:$A$1453,Sheet2!$B$2:$B$1453),_xlfn.XLOOKUP(A59,TEXT(Sheet2!$A$2:$A$1453,"0"),Sheet2!$B$2:$B$1453,""))} -> PANTENE SHAMPOO ANTI DANDRUFF | C59: 14.84 | D59: {=_xlfn.LET(_xlpm.v,IFERROR(_xlfn.XLOOKUP(A59,Sheet2!$A$2:$A$1453,Sheet2!$D$2:$D$1453),_xlfn.XLOOKUP(A59,TEXT(Sheet2!$A$2:$A$1453,"0"),Sheet2!$D$2:$D$1453,"")),IF(_xlpm.v="","",IF(_xlpm.v<1,_xlpm.v*100,_xlpm.v)))} -> 15 | E59: =IF(D59="","",C59*(1-D59/100)) -> 12.614 | F59: {=IFERROR(_xlfn.XLOOKUP(A59,Sheet2!$A$2:$A$1453,Sheet2!$F$2:$F$1453),_xlfn.XLOOKUP(A59,TEXT(Sheet2!$A$2:$A$1453,"0"),Sheet2!$F$2:$F$1453,""))} -> 26-7-2026 | G59: {=IFERROR(_xlfn.XLOOKUP(A59,Sheet2!$A$2:$A$1453,Sheet2!$G$2:$G$1453),_xlfn.XLOOKUP(A59,TEXT(Sheet2!$A$2:$A$1453,"0"),Sheet2!$G$2:$G$1453,""))} -> 6-8-2026
A60: 20309012311 | B60: {=IFERROR(_xlfn.XLOOKUP(A60,Sheet2!$A$2:$A$1453,Sheet2!$B$2:$B$1453),_xlfn.XLOOKUP(A60,TEXT(Sheet2!$A$2:$A$1453,"0"),Sheet2!$B$2:$B$1453,""))} -> PANTENE SHAMPOO ANTI HAIR FALL 3 | C60: 14.84 | D60: {=_xlfn.LET(_xlpm.v,IFERROR(_xlfn.XLOOKUP(A60,Sheet2!$A$2:$A$1453,Sheet2!$D$2:$D$1453),_xlfn.XLOOKUP(A60,TEXT(Sheet2!$A$2:$A$1453,"0"),Sheet2!$D$2:$D$1453,"")),IF(_xlpm.v="","",IF(_xlpm.v<1,_xlpm.v*100,_xlpm.v)))} -> 15 | E60: =IF(D60="","",C60*(1-D60/100)) -> 12.614 | F60: {=IFERROR(_xlfn.XLOOKUP(A60,Sheet2!$A$2:$A$1453,Sheet2!$F$2:$F$1453),_xlfn.XLOOKUP(A60,TEXT(Sheet2!$A$2:$A$1453,"0"),Sheet2!$F$2:$F$1453,""))} -> 26-7-2026 | G60: {=IFERROR(_xlfn.XLOOKUP(A60,Sheet2!$A$2:$A$1453,Sheet2!$G$2:$G$1453),_xlfn.XLOOKUP(A60,TEXT(Sheet2!$A$2:$A$1453,"0"),Sheet2!$G$2:$G$1453,""))} -> 6-8-2026
A61: 20309012310 | B61: {=IFERROR(_xlfn.XLOOKUP(A61,Sheet2!$A$2:$A$1453,Sheet2!$B$2:$B$1453),_xlfn.XLOOKUP(A61,TEXT(Sheet2!$A$2:$A$1453,"0"),Sheet2!$B$2:$B$1453,""))} -> PANTENE SHAMPOO SMOOTH & SILKY | C61: 14.84 | D61: {=_xlfn.LET(_xlpm.v,IFERROR(_xlfn.XLOOKUP(A61,Sheet2!$A$2:$A$1453,Sheet2!$D$2:$D$1453),_xlfn.XLOOKUP(A61,TEXT(Sheet2!$A$2:$A$1453,"0"),Sheet2!$D$2:$D$1453,"")),IF(_xlpm.v="","",IF(_xlpm.v<1,_xlpm.v*100,_xlpm.v)))} -> 15 | E61: =IF(D61="","",C61*(1-D61/100)) -> 12.614 | F61: {=IFERROR(_xlfn.XLOOKUP(A61,Sheet2!$A$2:$A$1453,Sheet2!$F$2:$F$1453),_xlfn.XLOOKUP(A61,TEXT(Sheet2!$A$2:$A$1453,"0"),Sheet2!$F$2:$F$1453,""))} -> 26-7-2026 | G61: {=IFERROR(_xlfn.XLOOKUP(A61,Sheet2!$A$2:$A$1453,Sheet2!$G$2:$G$1453),_xlfn.XLOOKUP(A61,TEXT(Sheet2!$A$2:$A$1453,"0"),Sheet2!$G$2:$G$1453,""))} -> 6-8-2026
A62: 20309012233 | B62: {=IFERROR(_xlfn.XLOOKUP(A62,Sheet2!$A$2:$A$1453,Sheet2!$B$2:$B$1453),_xlfn.XLOOKUP(A62,TEXT(Sheet2!$A$2:$A$1453,"0"),Sheet2!$B$2:$B$1453,""))} -> PANTENE SHAMPO CURLYSTIC 400 ML | C62: 31.79 | D62: {=_xlfn.LET(_xlpm.v,IFERROR(_xlfn.XLOOKUP(A62,Sheet2!$A$2:$A$1453,Sheet2!$D$2:$D$1453),_xlfn.XLOOKUP(A62,TEXT(Sheet2!$A$2:$A$1453,"0"),Sheet2!$D$2:$D$1453,"")),IF(_xlpm.v="","",IF(_xlpm.v<1,_xlpm.v*100,_xlpm.v)))} -> 15 | E62: =IF(D62="","",C62*(1-D62/100)) -> 27.0215 | F62: {=IFERROR(_xlfn.XLOOKUP(A62,Sheet2!$A$2:$A$1453,Sheet2!$F$2:$F$1453),_xlfn.XLOOKUP(A62,TEXT(Sheet2!$A$2:$A$1453,"0"),Sheet2!$F$2:$F$1453,""))} -> 26-7-2026 | G62: {=IFERROR(_xlfn.XLOOKUP(A62,Sheet2!$A$2:$A$1453,Sheet2!$G$2:$G$1453),_xlfn.XLOOKUP(A62,TEXT(Sheet2!$A$2:$A$1453,"0"),Sheet2!$G$2:$G$1453,""))} -> 6-8-2026
A63: 20309012212 | B63: {=IFERROR(_xlfn.XLOOKUP(A63,Sheet2!$A$2:$A$1453,Sheet2!$B$2:$B$1453),_xlfn.XLOOKUP(A63,TEXT(Sheet2!$A$2:$A$1453,"0"),Sheet2!$B$2:$B$1453,""))} -> HERBAL ESSNS SHAMPO PURE ALOE&AVOCADO 400 ML | C63: 27.6 | D63: {=_xlfn.LET(_xlpm.v,IFERROR(_xlfn.XLOOKUP(A63,Sheet2!$A$2:$A$1453,Sheet2!$D$2:$D$1453),_xlfn.XLOOKUP(A63,TEXT(Sheet2!$A$2:$A$1453,"0"),Sheet2!$D$2:$D$1453,"")),IF(_xlpm.v="","",IF(_xlpm.v<1,_xlpm.v*100,_xlpm.v)))} -> 15 | E63: =IF(D63="","",C63*(1-D63/100)) -> 23.46 | F63: {=IFERROR(_xlfn.XLOOKUP(A63,Sheet2!$A$2:$A$1453,Sheet2!$F$2:$F$1453),_xlfn.XLOOKUP(A63,TEXT(Sheet2!$A$2:$A$1453,"0"),Sheet2!$F$2:$F$1453,""))} -> 26-7-2026 | G63: {=IFERROR(_xlfn.XLOOKUP(A63,Sheet2!$A$2:$A$1453,Sheet2!$G$2:$G$1453),_xlfn.XLOOKUP(A63,TEXT(Sheet2!$A$2:$A$1453,"0"),Sheet2!$G$2:$G$1453,""))} -> 6-8-2026
A64: 20309011950 | B64: {=IFERROR(_xlfn.XLOOKUP(A64,Sheet2!$A$2:$A$1453,Sheet2!$B$2:$B$1453),_xlfn.XLOOKUP(A64,TEXT(Sheet2!$A$2:$A$1453,"0"),Sheet2!$B$2:$B$1453,""))} -> Pantene hair shampo daily care 1000ml 61775 | C64: 42.11 | D64: {=_xlfn.LET(_xlpm.v,IFERROR(_xlfn.XLOOKUP(A64,Sheet2!$A$2:$A$1453,Sheet2!$D$2:$D$1453),_xlfn.XLOOKUP(A64,TEXT(Sheet2!$A$2:$A$1453,"0"),Sheet2!$D$2:$D$1453,"")),IF(_xlpm.v="","",IF(_xlpm.v<1,_xlpm.v*100,_xlpm.v)))} -> 15 | E64: =IF(D64="","",C64*(1-D64/100)) -> 35.7935 | F64: {=IFERROR(_xlfn.XLOOKUP(A64,Sheet2!$A$2:$A$1453,Sheet2!$F$2:$F$1453),_xlfn.XLOOKUP(A64,TEXT(Sheet2!$A$2:$A$1453,"0"),Sheet2!$F$2:$F$1453,""))} -> 26-7-2026 | G64: {=IFERROR(_xlfn.XLOOKUP(A64,Sheet2!$A$2:$A$1453,Sheet2!$G$2:$G$1453),_xlfn.XLOOKUP(A64,TEXT(Sheet2!$A$2:$A$1453,"0"),Sheet2!$G$2:$G$1453,""))} -> 6-8-2026
...

Sheet Sheet2
A1: ATS CODE | B1: الصنف | C1: السعر قبل العرض | D1: نسبة خصم العرض | E1: السعر بعد العرض | F1: بداية المدة | G1: نهاية المدة | H1: موجود في شيت1؟
A2: 20615010023 | B2: PAMPERS PANTS MEGA NO-3 2X60 | C2: 76 | D2: 15 | E2: 64.6 | F2: 26-7-2026 | G2: 6-8-2026 | H2: =IF(COUNTIF(Sheet1!$A:$A,TEXT(A2,"0"))+COUNTIF(Sheet1!$A:$A,A2)>0,"موجود","غير موجود") -> موجود
A3: 20615010401 | B3: PAMPERS PREMUM CARE PANTS BOX NO-6 1X54 | C3: 135 | D3: 12.5 | E3: 118.125 | F3: 26-7-2026 | G3: 6-8-2026 | H3: =IF(COUNTIF(Sheet1!$A:$A,TEXT(A3,"0"))+COUNTIF(Sheet1!$A:$A,A3)>0,"موجود","غير موجود") -> موجود
A4: 20615010404 | B4: PAMPERS PREMUM CARE PANTS NO-4 2X50 | C4: 80 | D4: 15 | E4: 68 | F4: 26-7-2026 | G4: 6-8-2026 | H4: =IF(COUNTIF(Sheet1!$A:$A,TEXT(A4,"0"))+COUNTIF(Sheet1!$A:$A,A4)>0,"موجود","غير موجود") -> موجود
A5: 20615010263 | B5: PAMPERS BOX JUMBO NO-1 1X136 | C5: 97 | D5: 12.5 | E5: 84.875 | F5: 26-7-2026 | G5: 5-10-2026 | H5: =IF(COUNTIF(Sheet1!$A:$A,TEXT(A5,"0"))+COUNTIF(Sheet1!$A:$A,A5)>0,"موجود","غير موجود") -> غير موجود
A6: 20615010265 | B6: PAMPERS BOX JUMBO NO-2 1X136. | C6: 97 | D6: 12.5 | E6: 84.875 | F6: 26-7-2026 | G6: 5-10-2026 | H6: =IF(COUNTIF(Sheet1!$A:$A,TEXT(A6,"0"))+COUNTIF(Sheet1!$A:$A,A6)>0,"موجود","غير موجود") -> غير موجود
A7: 20615010266 | B7: PAMPERS BOX JUMBO NO-3 1X104 | C7: 97 | D7: 12.5 | E7: 84.875 | F7: 26-7-2026 | G7: 5-10-2026 | H7: =IF(COUNTIF(Sheet1!$A:$A,TEXT(A7,"0"))+COUNTIF(Sheet1!$A:$A,A7)>0,"موجود","غير موجود") -> غير موجود
A8: 20615010267 | B8: PAMPERS BOX JUMBO NO-4 1X96 | C8: 97 | D8: 12.5 | E8: 84.875 | F8: 26-7-2026 | G8: 5-10-2026 | H8: =IF(COUNTIF(Sheet1!$A:$A,TEXT(A8,"0"))+COUNTIF(Sheet1!$A:$A,A8)>0,"موجود","غير موجود") -> موجود
A9: 20615010268 | B9: PAMPERS BOX JUMBO NO-5 1X80 | C9: 97 | D9: 12.5 | E9: 84.875 | F9: 26-7-2026 | G9: 5-10-2026 | H9: =IF(COUNTIF(Sheet1!$A:$A,TEXT(A9,"0"))+COUNTIF(Sheet1!$A:$A,A9)>0,"موجود","غير موجود") -> غير موجود
A10: 20615010269 | B10: PAMPERS BOX JUMBO NO-6 1X58 | C10: 97 | D10: 12.5 | E10: 84.875 | F10: 26-7-2026 | G10: 5-10-2026 | H10: =IF(COUNTIF(Sheet1!$A:$A,TEXT(A10,"0"))+COUNTIF(Sheet1!$A:$A,A10)>0,"موجود","غير موجود") -> موجود
A11: 20615010175 | B11: PAMPERS NO-3 2X84 | C11: 76 | D11: 12.5 | E11: 66.5 | F11: 26-7-2026 | G11: 5-10-2026 | H11: =IF(COUNTIF(Sheet1!$A:$A,TEXT(A11,"0"))+COUNTIF(Sheet1!$A:$A,A11)>0,"موجود","غير موجود") -> موجود
A12: 20615010110 | B12: pampers mega no 4 2*76 | C12: 76 | D12: 12.5 | E12: 66.5 | F12: 26-7-2026 | G12: 5-10-2026 | H12: =IF(COUNTIF(Sheet1!$A:$A,TEXT(A12,"0"))+COUNTIF(Sheet1!$A:$A,A12)>0,"موجود","غير موجود") -> موجود
A13: 20615010109 | B13: PAMPERS NO-4+ 2X74 | C13: 76 | D13: 12.5 | E13: 66.5 | F13: 26-7-2026 | G13: 5-10-2026 | H13: =IF(COUNTIF(Sheet1!$A:$A,TEXT(A13,"0"))+COUNTIF(Sheet1!$A:$A,A13)>0,"موجود","غير موجود") -> غير موجود
... A99: 20309012329 | B99: HEAD AND SHOULDERS SHAMPO ICE F | C99: 15.13 | D99: 15 | E99: 12.8605 | F99: 26-7-2026 | G99: 6-8-2026 | H99: =IF(COUNTIF(Sheet1!$A:$A,TEXT(A99,"0"))+COUNTIF(Sheet1!$A:$A,A99)>0,"موجود","غير موجود") -> غير موجود
A100: 1-14-201-014 | B100: UNIDOVE FEMINE VAGINAL WASH /1ML | C100: 85 | D100: 20 | E100: 68 | F100: 26-7-2026 | G100: 6-8-2026 | H100: =IF(COUNTIF(Sheet1!$A:$A,TEXT(A100,"0"))+COUNTIF(Sheet1!$A:$A,A100)>0,"موجود","غير موجود") -> موجود
A101: 2-09-031-398 | B101: UNIDOVE COLLAGEN Cream /1Container, | C101: 180 | D101: 20 | E101: 144 | F101: 26-7-2026 | G101: 6-8-2026 | H101: =IF(COUNTIF(Sheet1!$A:$A,TEXT(A101,"0"))+COUNTIF(Sheet1!$A:$A,A101)>0,"موجود","غير موجود") -> موجود
A102: 2-09-031-399 | B102: UNIDOVE SUN SCREEN Cream /1Containe | C102: 125 | D102: 20 | E102: 100 | F102: 26-7-2026 | G102: 6-8-2026 | H102: =IF(COUNTIF(Sheet1!$A:$A,TEXT(A102,"0"))+COUNTIF(Sheet1!$A:$A,A102)>0,"موجود","غير موجود") -> غير موجود
A103: 2-09-031-529 | B103: UNIDOVE SUN SCREEN container Lotion, | C103: 115 | D103: 20 | E103: 92 | F103: 26-7-2026 | G103: 6-8-2026 | H103: =IF(COUNTIF(Sheet1!$A:$A,TEXT(A103,"0"))+COUNTIF(Sheet1!$A:$A,A103)>0,"موجود","غير موجود") -> موجود
A104: 2-09-066-103 | B104: UNIDOVE WHITENING SOAP container So | C104: 47 | D104: 20 | E104: 37.6 | F104: 26-7-2026 | G104: 6-8-2026 | H104: =IF(COUNTIF(Sheet1!$A:$A,TEXT(A104,"0"))+COUNTIF(Sheet1!$A:$A,A104)>0,"موجود","غير موجود") -> غير موجود
A105: 2-09-066-104 | B105: UNIDOVE CLEANSING SOAP container So | C105: 42 | D105: 20 | E105: 33.6 | F105: 26-7-2026 | G105: 6-8-2026 | H105: =IF(COUNTIF(Sheet1!$A:$A,TEXT(A105,"0"))+COUNTIF(Sheet1!$A:$A,A105)>0,"موجود","غير موجود") -> موجود
A106: 2-09-092-022 | B106: UNIDOVE FACIAL CLEANSER Liquid /1Co | C106: 125 | D106: 20 | E106: 100 | F106: 26-7-2026 | G106: 6-8-2026 | H106: =IF(COUNTIF(Sheet1!$A:$A,TEXT(A106,"0"))+COUNTIF(Sheet1!$A:$A,A106)>0,"موجود","غير موجود") -> موجود
A107: 2-09-094-076 | B107: UNIDOVE BODY LOTION /1Container, 1Co | C107: 125 | D107: 20 | E107: 100 | F107: 26-7-2026 | G107: 6-8-2026 | H107: =IF(COUNTIF(Sheet1!$A:$A,TEXT(A107,"0"))+COUNTIF(Sheet1!$A:$A,A107)>0,"موجود","غير موجود") -> غير موجود
A108: 2-09-149-045 | B108: UNIDOVE ALICE Serum /1Container, 1Cont | C108: 145 | D108: 20 | E108: 116 | F108: 26-7-2026 | G108: 6-8-2026 | H108: =IF(COUNTIF(Sheet1!$A:$A,TEXT(A108,"0"))+COUNTIF(Sheet1!$A:$A,A108)>0,"موجود","غير موجود") -> غير موجود
A109: 2-09-149-063 | B109: NANO DERMA VITAMIN C SERUM 30 M | C109: 170.00001 | D109: 20 | E109: 136.00001 | F109: 26-7-2026 | G109: 6-8-2026 | H109: =IF(COUNTIF(Sheet1!$A:$A,TEXT(A109,"0"))+COUNTIF(Sheet1!$A:$A,A109)>0,"موجود","غير موجود") -> غير موجود
A110: 2-09-149-068 | B110: UNIDOVE HAIR CREAM 100 ML/CONTA | C110: 95 | D110: 20 | E110: 76 | F110: 26-7-2026 | G110: 6-8-2026 | H110: =IF(COUNTIF(Sheet1!$A:$A,TEXT(A110,"0"))+COUNTIF(Sheet1!$A:$A,A110)>0,"موجود","غير موجود") -> غير موجود
A111: 2-09-150-081 | B111: UNIDOVE ALICE shampoo /1Container, 1C | C111: 95 | D111: 20 | E111: 76 | F111: 26-7-2026 | G111: 6-8-2026 | H111: =IF(COUNTIF(Sheet1!$A:$A,TEXT(A111,"0"))+COUNTIF(Sheet1!$A:$A,A111)>0,"موجود","غير موجود") -> موجود
... A126: 1-03-186-068 | B126: NQ ARGITONE ml Syrup, 100 ML/BOTTLE | C126: 150 | D126: 33 | E126: 100.5 | F126: 26-7-2026 | G126: 6-8-2026 | H126: =IF(COUNTIF(Sheet1!$A:$A,TEXT(A126,"0"))+COUNTIF(Sheet1!$A:$A,A126)>0,"موجود","غير موجود") -> موجود
A127: 20715010050 | B127: BLEMIL PLUS NO (1) 800 GM | C127: 88.5 | D127: 10 | E127: 79.65 | F127: 26-7-2026 | G127: 5-10-2026 | H127: =IF(COUNTIF(Sheet1!$A:$A,TEXT(A127,"0"))+COUNTIF(Sheet1!$A:$A,A127)>0,"موجود","غير موجود") -> موجود
A128: 20715010042 | B128: BLEMIL PLUS 2 800G | C128: 88.5 | D128: 10 | E128: 79.65 | F128: 26-7-2026 | G128: 5-10-2026 | H128: =IF(COUNTIF(Sheet1!$A:$A,TEXT(A128,"0"))+COUNTIF(Sheet1!$A:$A,A128)>0,"موجود","غير موجود") -> موجود
A129: 20715010051 | B129: BLEMIL PLUS NO (3) 800 GM | C129: 86 | D129: 10 | E129: 77.4 | F129: 26-7-2026 | G129: 5-10-2026 | H129: =IF(COUNTIF(Sheet1!$A:$A,TEXT(A129,"0"))+COUNTIF(Sheet1!$A:$A,A129)>0,"موجود","غير موجود") -> موجود
A130: 20715010265 | B130: BLEMIL PLUS ( 3 ) 1200 | C130: 126 | D130: 10 | E130: 113.4 | F130: 26-7-2026 | G130: 5-10-2026 | H130: =IF(COUNTIF(Sheet1!$A:$A,TEXT(A130,"0"))+COUNTIF(Sheet1!$A:$A,A130)>0,"موجود","غير موجود") -> موجود
A131: 20715010481 | B131: BLEVIT MULTIGRAIN AND FIBER 0% AD | C131: 28.66 | D131: 25 | E131: 21.495 | F131: 26-7-2026 | G131: 5-10-2026 | H131: =IF(COUNTIF(Sheet1!$A:$A,TEXT(A131,"0"))+COUNTIF(Sheet1!$A:$A,A131)>0,"موجود","غير موجود") -> غير موجود
A132: 20815010011 | B132: BLEVIT PLUS AD CARROT&RICE 0% ADD | C132: 28.66 | D132: 25 | E132: 21.495 | F132: 26-7-2026 | G132: 5-10-2026 | H132: =IF(COUNTIF(Sheet1!$A:$A,TEXT(A132,"0"))+COUNTIF(Sheet1!$A:$A,A132)>0,"موجود","غير موجود") -> غير موجود
A133: 20715010480 | B133: BLEVIT PLUS TO SHAKE 0% ADDED SUG | C133: 28.66 | D133: 25 | E133: 21.495 | F133: 26-7-2026 | G133: 5-10-2026 | H133: =IF(COUNTIF(Sheet1!$A:$A,TEXT(A133,"0"))+COUNTIF(Sheet1!$A:$A,A133)>0,"موجود","غير موجود") -> غير موجود
A134: 20815010012 | B134: BLEVIT RICE AND FRUITS WITH MILK 3 | C134: 28.66 | D134: 25 | E134: 21.495 | F134: 26-7-2026 | G134: 5-10-2026 | H134: =IF(COUNTIF(Sheet1!$A:$A,TEXT(A134,"0"))+COUNTIF(Sheet1!$A:$A,A134)>0,"موجود","غير موجود") -> غير موجود
A135: 20815010041 | B135: BLEVIT RICE WITH MILK 350 GM | C135: 28.66 | D135: 25 | E135: 21.495 | F135: 26-7-2026 | G135: 5-10-2026 | H135: =IF(COUNTIF(Sheet1!$A:$A,TEXT(A135,"0"))+COUNTIF(Sheet1!$A:$A,A135)>0,"موجود","غير موجود") -> موجود
A136: 20815010007 | B136: BLEVIT WHEAT WITH MILK 350 GM | C136: 26 | D136: 25 | E136: 19.5 | F136: 26-7-2026 | G136: 5-10-2026 | H136: =IF(COUNTIF(Sheet1!$A:$A,TEXT(A136,"0"))+COUNTIF(Sheet1!$A:$A,A136)>0,"موجود","غير موجود") -> غير موجود
A137: 20715010482 | B137: VITAFOS 3+NUTRITONAL FORMULA FO | C137: 47 | D137: 30 | E137: 32.9 | F137: 26-7-2026 | G137: 5-10-2026 | H137: =IF(COUNTIF(Sheet1!$A:$A,TEXT(A137,"0"))+COUNTIF(Sheet1!$A:$A,A137)>0,"موجود","غير موجود") -> غير موجود
A138: 20715010232 | B138: VITAFOS NUTITIONAL MILK 400 | C138: 47 | D138: 30 | E138: 32.9 | F138: 26-7-2026 | G138: 5-10-2026 | H138: =IF(COUNTIF(Sheet1!$A:$A,TEXT(A138,"0"))+COUNTIF(Sheet1!$A:$A,A138)>0,"موجود","غير موجود") -> غير موجود
... A176: 20309503830 | B176: VAUVA BABY WIPES 80 PCS COTTON 100% BAGS 2+1 | C176: 32 | D176: 25 | E176: 24 | F176: 26-7-2026 | G176: 6-8-2026 | H176: =IF(COUNTIF(Sheet1!$A:$A,TEXT(A176,"0"))+COUNTIF(Sheet1!$A:$A,A176)>0,"موجود","غير موجود") -> موجود
...
