Workbook

Sheet لوحة المتابعة
B1: لوحة متابعة الأداء — مهام التجارة الإلكترونية والبيع أونالين
B2: صيدليات أوبلس • يوليو — ديسمبر 2026
B4: إجمالي المهام | C4: المكتملة (تم) | D4: قيد التنفيذ (جاري) | E4: لم تبدأ | F4: نسبة الإنجاز (تم) | G4: نسبة التقدم الكلي*
B5: =COUNTA(المهام!$C$3:$C$46) -> 44 | C5: =COUNTIF(المهام!$J$3:$J$46,"تم") -> 1 | D5: =COUNTIF(المهام!$J$3:$J$46,"جاري") -> 21 | E5: =COUNTIF(المهام!$J$3:$J$46,"لم يبدأ") -> 22 | F5: =COUNTIF(المهام!$J$3:$J$46,"تم")/COUNTA(المهام!$C$3:$C$46) -> 0.022727273 | G5: =(COUNTIF(المهام!$J$3:$J$46,"تم")+COUNTIF(المهام!$J$3:$J$46,"جاري")*0.5)/COUNTA(المهام!$C$3:$C$46) -> 0.26136364
B7: *نسبة التقدم الكلي تحتسب المهام «جاري» . آخر تحديث: 19 يوليو 2026
B9: الإنجاز حسب المشروع
B10: المحور / المشروع | C10: عدد المهام | D10: تم | E10: جاري | F10: لم يبدأ | G10: نسبة الإنجاز
B11: الهيكل الوظيفي | C11: =COUNTIF(المهام!$B$3:$B$46,"الهيكل الوظيفي") -> 3 | D11: =COUNTIFS(المهام!$B$3:$B$46,"الهيكل الوظيفي",المهام!$J$3:$J$46,"تم") -> 0 | E11: =COUNTIFS(المهام!$B$3:$B$46,"الهيكل الوظيفي",المهام!$J$3:$J$46,"جاري") -> 3 | F11: =COUNTIFS(المهام!$B$3:$B$46,"الهيكل الوظيفي",المهام!$J$3:$J$46,"لم يبدأ") -> 0 | G11: =IFERROR(D11/C11,0) -> 0
B12: منصة زد (الباقة الاحترافية) | C12: =COUNTIF(المهام!$B$3:$B$46,"منصة زد (الباقة الاحترافية)") -> 4 | D12: =COUNTIFS(المهام!$B$3:$B$46,"منصة زد (الباقة الاحترافية)",المهام!$J$3:$J$46,"تم") -> 0 | E12: =COUNTIFS(المهام!$B$3:$B$46,"منصة زد (الباقة الاحترافية)",المهام!$J$3:$J$46,"جاري") -> 0 | F12: =COUNTIFS(المهام!$B$3:$B$46,"منصة زد (الباقة الاحترافية)",المهام!$J$3:$J$46,"لم يبدأ") -> 4 | G12: =IFERROR(D12/C12,0) -> 0
B13: مشروع جوليب | C13: =COUNTIF(المهام!$B$3:$B$46,"مشروع جوليب") -> 4 | D13: =COUNTIFS(المهام!$B$3:$B$46,"مشروع جوليب",المهام!$J$3:$J$46,"تم") -> 0 | E13: =COUNTIFS(المهام!$B$3:$B$46,"مشروع جوليب",المهام!$J$3:$J$46,"جاري") -> 3 | F13: =COUNTIFS(المهام!$B$3:$B$46,"مشروع جوليب",المهام!$J$3:$J$46,"لم يبدأ") -> 1 | G13: =IFERROR(D13/C13,0) -> 0
B14: منصة Linkit | C14: =COUNTIF(المهام!$B$3:$B$46,"منصة Linkit") -> 3 | D14: =COUNTIFS(المهام!$B$3:$B$46,"منصة Linkit",المهام!$J$3:$J$46,"تم") -> 0 | E14: =COUNTIFS(المهام!$B$3:$B$46,"منصة Linkit",المهام!$J$3:$J$46,"جاري") -> 0 | F14: =COUNTIFS(المهام!$B$3:$B$46,"منصة Linkit",المهام!$J$3:$J$46,"لم يبدأ") -> 3 | G14: =IFERROR(D14/C14,0) -> 0
B15: تفعيل تابي | C15: =COUNTIF(المهام!$B$3:$B$46,"تفعيل تابي") -> 3 | D15: =COUNTIFS(المهام!$B$3:$B$46,"تفعيل تابي",المهام!$J$3:$J$46,"تم") -> 0 | E15: =COUNTIFS(المهام!$B$3:$B$46,"تفعيل تابي",المهام!$J$3:$J$46,"جاري") -> 0 | F15: =COUNTIFS(المهام!$B$3:$B$46,"تفعيل تابي",المهام!$J$3:$J$46,"لم يبدأ") -> 3 | G15: =IFERROR(D15/C15,0) -> 0
B16: تطبيق الموبايل | C16: =COUNTIF(المهام!$B$3:$B$46,"تطبيق الموبايل") -> 4 | D16: =COUNTIFS(المهام!$B$3:$B$46,"تطبيق الموبايل",المهام!$J$3:$J$46,"تم") -> 0 | E16: =COUNTIFS(المهام!$B$3:$B$46,"تطبيق الموبايل",المهام!$J$3:$J$46,"جاري") -> 2 | F16: =COUNTIFS(المهام!$B$3:$B$46,"تطبيق الموبايل",المهام!$J$3:$J$46,"لم يبدأ") -> 2 | G16: =IFERROR(D16/C16,0) -> 0
B17: اتفاقيات التوصيل | C17: =COUNTIF(المهام!$B$3:$B$46,"اتفاقيات التوصيل") -> 3 | D17: =COUNTIFS(المهام!$B$3:$B$46,"اتفاقيات التوصيل",المهام!$J$3:$J$46,"تم") -> 0 | E17: =COUNTIFS(المهام!$B$3:$B$46,"اتفاقيات التوصيل",المهام!$J$3:$J$46,"جاري") -> 0 | F17: =COUNTIFS(المهام!$B$3:$B$46,"اتفاقيات التوصيل",المهام!$J$3:$J$46,"لم يبدأ") -> 3 | G17: =IFERROR(D17/C17,0) -> 0
B18: منظومة واتساب والرقم الموحد | C18: =COUNTIF(المهام!$B$3:$B$46,"منظومة واتساب والرقم الموحد") -> 4 | D18: =COUNTIFS(المهام!$B$3:$B$46,"منظومة واتساب والرقم الموحد",المهام!$J$3:$J$46,"تم") -> 1 | E18: =COUNTIFS(المهام!$B$3:$B$46,"منظومة واتساب والرقم الموحد",المهام!$J$3:$J$46,"جاري") -> 3 | F18: =COUNTIFS(المهام!$B$3:$B$46,"منظومة واتساب والرقم الموحد",المهام!$J$3:$J$46,"لم يبدأ") -> 0 | G18: =IFERROR(D18/C18,0) -> 0.25
B19: عمليات المتجر | C19: =COUNTIF(المهام!$B$3:$B$46,"عمليات المتجر") -> 5 | D19: =COUNTIFS(المهام!$B$3:$B$46,"عمليات المتجر",المهام!$J$3:$J$46,"تم") -> 0 | E19: =COUNTIFS(المهام!$B$3:$B$46,"عمليات المتجر",المهام!$J$3:$J$46,"جاري") -> 4 | F19: =COUNTIFS(المهام!$B$3:$B$46,"عمليات المتجر",المهام!$J$3:$J$46,"لم يبدأ") -> 1 | G19: =IFERROR(D19/C19,0) -> 0
B20: التسويق والحملات | C20: =COUNTIF(المهام!$B$3:$B$46,"التسويق والحملات") -> 6 | D20: =COUNTIFS(المهام!$B$3:$B$46,"التسويق والحملات",المهام!$J$3:$J$46,"تم") -> 0 | E20: =COUNTIFS(المهام!$B$3:$B$46,"التسويق والحملات",المهام!$J$3:$J$46,"جاري") -> 3 | F20: =COUNTIFS(المهام!$B$3:$B$46,"التسويق والحملات",المهام!$J$3:$J$46,"لم يبدأ") -> 3 | G20: =IFERROR(D20/C20,0) -> 0
B21: البنية التشغيلية والصيانة | C21: =COUNTIF(المهام!$B$3:$B$46,"البنية التشغيلية والصيانة") -> 1 | D21: =COUNTIFS(المهام!$B$3:$B$46,"البنية التشغيلية والصيانة",المهام!$J$3:$J$46,"تم") -> 0 | E21: =COUNTIFS(المهام!$B$3:$B$46,"البنية التشغيلية والصيانة",المهام!$J$3:$J$46,"جاري") -> 0 | F21: =COUNTIFS(المهام!$B$3:$B$46,"البنية التشغيلية والصيانة",المهام!$J$3:$J$46,"لم يبدأ") -> 1 | G21: =IFERROR(D21/C21,0) -> 0
B22: التقارير والمتابعة | C22: =COUNTIF(المهام!$B$3:$B$46,"التقارير والمتابعة") -> 4 | D22: =COUNTIFS(المهام!$B$3:$B$46,"التقارير والمتابعة",المهام!$J$3:$J$46,"تم") -> 0 | E22: =COUNTIFS(المهام!$B$3:$B$46,"التقارير والمتابعة",المهام!$J$3:$J$46,"جاري") -> 3 | F22: =COUNTIFS(المهام!$B$3:$B$46,"التقارير والمتابعة",المهام!$J$3:$J$46,"لم يبدأ") -> 1 | G22: =IFERROR(D22/C22,0) -> 0
B23: الإجمالي | C23: =SUM(C11:C22) -> 44 | D23: =SUM(D11:D22) -> 1 | E23: =SUM(E11:E22) -> 21 | F23: =SUM(F11:F22) -> 22 | G23: =IFERROR(D23/C23,0) -> 0.022727273

Sheet المهام
A1: متابعة مهام التسويق الإلكتروني والبيع أونالين — صيدليات أوبلس
A2: م | B2: المحور / المشروع | C2: المهمة | D2: المسؤول (A) | E2: المنفّذ (C) | F2: المُخطَر (I) | G2: التكلفة | H2: تاريخ البداية | I2: تاريخ النهاية | J2: الحالة | K2: ملاحظات
A3: 1 | B3: الهيكل الوظيفي | C3: إجراء المقابلات واختيار مسؤول عمليات المتجر (صيدلانية من داخل الشركة) | D3: د. الحسن | E3: الموارد البشرية | F3: د. الزيني | J3: جاري | K3: يتم الاختيار بعد إجراء المقابلات
A4: 2 | B4: الهيكل الوظيفي | C4: تعيين وتفعيل دور أخصائي التسويق (أ. عائشة) | D4: د. الحسن | E4: الموارد البشرية | F4: د. الزيني | J4: جاري
A5: 3 | B5: الهيكل الوظيفي | C5: توزيع المهام والمسؤوليات على فريق التجارة الإلكترونية | D5: د. الحسن | E5: د. الحسن | F5: د. الزيني | J5: جاري
A6: 4 | B6: منصة زد (الباقة الاحترافية) | C6: تفعيل الباقة الاحترافية على منصة زد | D6: د. الحسن | E6: د. الحسن | F6: د. الزيني | J6: لم يبدأ
A7: 5 | B7: منصة زد (الباقة الاحترافية) | C7: تعيين مدير حساب متخصص من زد لدعم مسؤول العمليات | D7: د. الحسن | E7: منصة زد | F7: د. الزيني | J7: لم يبدأ
A8: 6 | B8: منصة زد (الباقة الاحترافية) | C8: تدريب مسؤول عمليات المتجر على إدارة المنصة | D8: د. الحسن | E8: منصة زد | F8: د. الزيني | J8: لم يبدأ
A9: 7 | B9: منصة زد (الباقة الاحترافية) | C9: الاستفادة من خصائص وتقارير الباقة الاحترافية في تحسين الأداء | D9: د. الحسن | E9: مسؤول عمليات المتجر | F9: د. الزيني | J9: لم يبدأ
A10: 8 | B10: مشروع جوليب | C10: التواصل المباشر مع شركة جوليب وعقد الاجتماعات | D10: د. الحسن | E10: د. الحسن | F10: د. الزيني | J10: جاري
A11: 9 | B11: مشروع جوليب | C11: زيارة مواقع تم تفعيل نظام جوليب ومعاينة التشغيل الفعلي | D11: د. الحسن | E11: د. الحسن | F11: د. الزيني | J11: لم يبدأ
A12: 10 | B12: مشروع جوليب | C12: دراسة إمكانية تكامل جوليب مع أنظمة أوبلس | D12: د. الحسن | E12: د. الحسن | F12: د. الزيني | J12: جاري
A13: 11 | B13: مشروع جوليب | C13: إعداد التقرير النهائي والتوصية بشأن تفعيل جوليب | D13: د. الحسن | E13: د. الحسن | F13: د. الزيني | J13: جاري
A14: 12 | B14: منصة Linkit | C14: ربط المتجر الإلكتروني بالمنصات الخارجية عبر Linkit | D14: د. الحسن | E14: د. الحسن | F14: د. الزيني | J14: لم يبدأ
A15: 13 | B15: منصة Linkit | C15: الربط مع هنقرستيشن وجاهز ومرسول عبر Linkit | D15: د. الحسن | E15: د. الحسن | F15: د. الزيني | J15: لم يبدأ
... A19: 17 | B19: تفعيل تابي | C19: تدريب مسؤول العمليات على متابعة طلبات تابي | D19: د. الحسن | E19: د. الحسن | F19: د. الزيني | J19: لم يبدأ
A20: 18 | B20: تطبيق الموبايل | C20: استكمال حسابات المطورين ومتابعة اعتماد المستندات | D20: د. الحسن | E20: د. الحسن | F20: د. الزيني | J20: جاري | K20: App Store + Google Play
A21: 19 | B21: تطبيق الموبايل | C21: استلام النسخة التجريبية واختبارها داخليًا وتسجيل الملاحظات | D21: د. الحسن | E21: د. الحسن | F21: د. الزيني | J21: لم يبدأ
A22: 20 | B22: تطبيق الموبايل | C22: رفع التطبيق على المنصات ومتابعة الاعتماد | D22: د. الحسن | E22: د. الحسن | F22: د. الزيني | J22: جاري
A23: 21 | B23: تطبيق الموبايل | C23: الإطلاق الرسمي للتطبيق ومتابعة التقييمات | D23: د. الحسن | E23: د. الحسن | F23: د. الزيني | J23: لم يبدأ
A24: 22 | B24: اتفاقيات التوصيل | C24: دراسة والتفاوض مع شركات التوصيل لتغطية المناطق غير المغطاة | D24: د. الحسن | E24: د. الحسن | F24: د. الزيني | J24: لم يبدأ
A25: 23 | B25: اتفاقيات التوصيل | C25: توقيع اتفاقيات مستوى الخدمة (SLA) مع شركات التوصيل | D25: د. الحسن | E25: د. الحسن | F25: د. الزيني | J25: لم يبدأ
A26: 24 | B26: اتفاقيات التوصيل | C26: التوسع في التوصيل إلى الرياض ووادي الدواسر والحوطة والسليل | D26: د. الحسن | E26: د. الحسن | F26: د. الزيني | J26: لم يبدأ
A27: 25 | B27: منظومة واتساب والرقم الموحد | C27: تخصيص رقم/كود خاص لطلبات واتساب لقياس مبيعات الرقم الموحد | D27: د. الحسن | E27: د. الحسن | F27: د. الزيني | J27: جاري | K27: خطوة قادمة — بدء العمل
A28: 26 | B28: منظومة واتساب والرقم الموحد | C28: تجهيز وتشغيل الصيدليات المستهدفة للوصول إلى 20 صيدلية مفعّلة | D28: د. الحسن | E28: كحلي | F28: د. الزيني | J28: جاري | K28: 15 من 20 مفعّلة حاليًا
A29: 27 | B29: منظومة واتساب والرقم الموحد | C29: فصل وقياس مبيعات واتساب بدقة | D29: د. الحسن | E29: د. الحسن | F29: د. الزيني | J29: جاري
A30: 28 | B30: منظومة واتساب والرقم الموحد | C30: تفعيل رسائل واتساب التلقائية وإعادة التواصل مع العميل بعد الطلب | D30: د. الحسن | E30: أخصائي التسويق (أ. عائشة) | F30: د. الزيني | J30: تم | K30: تم التكامل بين المتجر وواتساب
A31: 29 | B31: عمليات المتجر | C31: إضافة وتحديث المنتجات ومراجعة الأسعار والعروض | D31: د. الحسن | E31: مسؤول عمليات المتجر | F31: د. الزيني | J31: جاري | K31: عملية مستمرة
A32: 30 | B32: عمليات المتجر | C32: متابعة المخزون والمنتجات غير المتوفرة | D32: د. الحسن | E32: مسؤول عمليات المتجر | F32: د. الزيني | J32: جاري | K32: عملية مستمرة
A33: 31 | B33: عمليات المتجر | C33: استقبال الطلبات وتوجيهها للفروع ومتابعة التجهيز والتسليم | D33: د. الحسن | E33: مسؤول عمليات المتجر | F33: د. الزيني | J33: جاري | K33: عملية مستمرة
A34: 32 | B34: عمليات المتجر | C34: متابعة الطلبات المتأخرة والملغاة والشكاوى التشغيلية | D34: د. الحسن | E34: مسؤول عمليات المتجر | F34: د. الزيني | J34: جاري
A35: 33 | B35: عمليات المتجر | C35: تنفيذ التحسينات المطلوبة على المتجر بالتنسيق مع مدير حساب زد | D35: د. الحسن | E35: مسؤول عمليات المتجر | F35: د. الزيني | J35: لم يبدأ
A36: 34 | B36: التسويق والحملات | C36: تحسين أداء الحملات التسويقية وزيادة معدل التحويل | D36: د. الحسن | E36: أخصائي التسويق (أ. عائشة) | F36: د. الزيني | J36: جاري
A37: 35 | B37: التسويق والحملات | C37: تنفيذ حملات إعادة استهداف العملاء السابقين | D37: د. الحسن | E37: أخصائي التسويق (أ. عائشة) | F37: د. الزيني | J37: لم يبدأ
A38: 36 | B38: التسويق والحملات | C38: متابعة السلات المتروكة وتنفيذ حملات استعادتها | D38: د. الحسن | E38: أخصائي التسويق (أ. عائشة) | F38: د. الزيني | J38: لم يبدأ
A39: 37 | B39: التسويق والحملات | C39: تنفيذ حملات الحفاظ على العملاء الحاليين | D39: د. الحسن | E39: أخصائي التسويق (أ. عائشة) | F39: د. الزيني | J39: لم يبدأ
A40: 38 | B40: التسويق والحملات | C40: متابعة أداء السوشيال ميديا وإعداد محتوى الحملات والعروض | D40: د. الحسن | E40: أخصائي التسويق (أ. عائشة) | F40: د. الزيني | J40: جاري
A41: 39 | B41: التسويق والحملات | C41: متابعة أداء شركة التسويق الخارجية والتنسيق معها | D41: د. الحسن | E41: د. الحسن | F41: د. الزيني | J41: جاري
A42: 40 | B42: البنية التشغيلية والصيانة | C42: الإشراف على تجهيزات المكتب وصيانة البنية التشغيلية | D42: د. الحسن | E42: كحلي | F42: د. الزيني | J42: لم يبدأ
A43: 41 | B43: التقارير والمتابعة | C43: إعداد التقارير اليومية (الطلبات، المبيعات، المخزون) | D43: د. الحسن | E43: مسؤول عمليات المتجر | F43: د. الزيني | J43: جاري
...
